2020-05-12 16:39:15.295 [error] <0.669.0> CRASH REPORT Process <0.669.0> with 0 neighbours exited with reason: {{{shutdown,{server_initiated_close,406,<<"PRECONDITION_FAILED - inequivalent arg 'x-dead-letter-exchange' for queue 'gen_server_test_queue' in vhost '/': received none but current is the value '' of type 'longstr'">>}},{gen_server,call,[<0.682.0>,{call,{'queue.declare',0,<<"gen_server_test_queue">>,false,true,false,false,false,[]},none,<0.669.0>},60000]}},{'Elixir.User.Plug.Router',call,[#{'__struct__' => 'Elixir.Plug.Conn',adapter => {'Elixir.Plug.Cowboy.Conn',#{bindings => #{},body_length => ...,...}},...},...]}} in 'Elixir.Plug.Cowboy.Handler':exit_on_error/4 line 76 in 'Elixir.Plug.Cowboy.Handler':exit_on_error/4 line 76
2020-05-12 16:39:15.312 [error] <0.669.0> Cowboy stream 1 with ranch listener 'Elixir.User.Plug.Router.HTTP' and connection process <0.668.0> had its request process exit with reason: {{{shutdown,{server_initiated_close,406,<<"PRECONDITION_FAILED - inequivalent arg 'x-dead-letter-exchange' for queue 'gen_server_test_queue' in vhost '/': received none but current is the value '' of type 'longstr'">>}},{gen_server,call,[<0.682.0>,{call,{'queue.declare',0,<<"gen_server_test_queue">>,false,true,false,false,false,[]},none,<0.669.0>},60000]}},{'Elixir.User.Plug.Router',call,[#{'__struct__' => 'Elixir.Plug.Conn',adapter => {'Elixir.Plug.Cowboy.Conn',#{bindings => #{},body_length => ...,...}},...},...]}} in 'Elixir.Plug.Cowboy.Handler':exit_on_error/4 line 76
2020-05-12 16:42:20.522 [error] <0.689.0> CRASH REPORT Process <0.689.0> with 0 neighbours exited with reason: {{{shutdown,{server_initiated_close,406,<<"PRECONDITION_FAILED - inequivalent arg 'x-dead-letter-exchange' for queue 'gen_server_test_queue' in vhost '/': received none but current is the value '' of type 'longstr'">>}},{gen_server,call,[<0.701.0>,{call,{'queue.declare',0,<<"gen_server_test_queue">>,false,true,false,false,false,[]},none,<0.689.0>},60000]}},{'Elixir.User.Plug.Router',call,[#{'__struct__' => 'Elixir.Plug.Conn',adapter => {'Elixir.Plug.Cowboy.Conn',#{bindings => #{},body_length => ...,...}},...},...]}} in 'Elixir.Plug.Cowboy.Handler':exit_on_error/4 line 76 in 'Elixir.Plug.Cowboy.Handler':exit_on_error/4 line 76
2020-05-12 16:42:20.522 [error] <0.689.0> Cowboy stream 1 with ranch listener 'Elixir.User.Plug.Router.HTTP' and connection process <0.688.0> had its request process exit with reason: {{{shutdown,{server_initiated_close,406,<<"PRECONDITION_FAILED - inequivalent arg 'x-dead-letter-exchange' for queue 'gen_server_test_queue' in vhost '/': received none but current is the value '' of type 'longstr'">>}},{gen_server,call,[<0.701.0>,{call,{'queue.declare',0,<<"gen_server_test_queue">>,false,true,false,false,false,[]},none,<0.689.0>},60000]}},{'Elixir.User.Plug.Router',call,[#{'__struct__' => 'Elixir.Plug.Conn',adapter => {'Elixir.Plug.Cowboy.Conn',#{bindings => #{},body_length => ...,...}},...},...]}} in 'Elixir.Plug.Cowboy.Handler':exit_on_error/4 line 76
2020-05-12 17:08:32.416 [error] <0.582.0>@lists:reverse:147 CRASH REPORT Process <0.582.0> with 0 neighbours crashed with reason: no function clause matching lists:reverse({ok,<<"{\"token\":\"eyJhbGciOiJIUzUxMiIsInR5cCI6IkpXVCJ9.eyJhdWQiOiJhdXRoIiwiZXhwIjoxNTkxODg0NTEyLCJp...">>}) line 147
2020-05-12 17:08:32.417 [error] <0.579.0>@lists:reverse:147 Supervisor {<0.579.0>,amqp_channel_sup} had child writer started with rabbit_writer:start_link(#Port<0.16>, 1, 131072, rabbit_framing_amqp_0_9_1, <0.581.0>, {<<"client 127.0.0.1:64373 -> 127.0.0.1:5672">>,1}, false, 1000000000) at <0.582.0> exit with reason no function clause matching lists:reverse({ok,<<"{\"token\":\"eyJhbGciOiJIUzUxMiIsInR5cCI6IkpXVCJ9.eyJhdWQiOiJhdXRoIiwiZXhwIjoxNTkxODg0NTEyLCJp...">>}) line 147 in context child_terminated
2020-05-12 17:08:32.417 [error] <0.579.0> Supervisor {<0.579.0>,amqp_channel_sup} had child writer started with rabbit_writer:start_link(#Port<0.16>, 1, 131072, rabbit_framing_amqp_0_9_1, <0.581.0>, {<<"client 127.0.0.1:64373 -> 127.0.0.1:5672">>,1}, false, 1000000000) at <0.582.0> exit with reason reached_max_restart_intensity in context shutdown
2020-05-12 17:08:32.433 [error] <0.568.0> CRASH REPORT Process <0.568.0> with 0 neighbours exited with reason: {{#{'__exception__' => true,'__struct__' => 'Elixir.Protocol.UndefinedError',description => <<>>,protocol => 'Elixir.String.Chars',value => {ok,<<"{\"token\":\"eyJhbGciOiJIUzUxMiIsInR5cCI6IkpXVCJ9.eyJhdWQiOiJhdXRoIiwiZXhwIjoxNTkxODg0NTEyLCJpYXQiOjE1ODkyOTI1MTIsImlzcyI6ImF1dGgiLCJqdGkiOiI1NzM3YmY0ZS03MDU0LTRiZTctODZhYy0xMDhmY2Q3ZGU5M2IiLCJuYmYiOjE1ODkyOTI1MTEsInN1YiI6IjMiLCJ0eXAiOiJhY2Nlc3MifQ.DiwNO2RJZyL3znS1qcGKGO0NBzto06132yxpJXF4iEOfKYPSWPWPSs88Yrjoshvkn-ptZLSWLVMhuldBtuXPbA\",\"last_name\":\"p...">>}},...},...} in 'Elixir.Plug.Cowboy.Handler':exit_on_error/4 line 68 in 'Elixir.Plug.Cowboy.Handler':exit_on_error/4 line 68
2020-05-12 17:08:32.441 [error] <0.568.0> Cowboy stream 1 with ranch listener 'Elixir.User.Plug.Router.HTTP' and connection process <0.567.0> had its request process exit with reason: {{#{'__exception__' => true,'__struct__' => 'Elixir.Protocol.UndefinedError',description => <<>>,protocol => 'Elixir.String.Chars',value => {ok,<<"{\"token\":\"eyJhbGciOiJIUzUxMiIsInR5cCI6IkpXVCJ9.eyJhdWQiOiJhdXRoIiwiZXhwIjoxNTkxODg0NTEyLCJpYXQiOjE1ODkyOTI1MTIsImlzcyI6ImF1dGgiLCJqdGkiOiI1NzM3YmY0ZS03MDU0LTRiZTctODZhYy0xMDhmY2Q3ZGU5M2IiLCJuYmYiOjE1ODkyOTI1MTEsInN1YiI6IjMiLCJ0eXAiOiJhY2Nlc3MifQ.DiwNO2RJZyL3znS1qcGKGO0NBzto06132yxpJXF4iEOfKYPSWPWPSs88Yrjoshvkn-ptZLSWLVMhuldBtuXPbA\",\"last_name\":\"p...">>}},...},...} in 'Elixir.Plug.Cowboy.Handler':exit_on_error/4 line 68
2020-05-26 15:18:14.910 [error] <0.662.0> CRASH REPORT Process <0.662.0> with 0 neighbours exited with reason: {{#{'__exception__' => true,'__struct__' => 'Elixir.DBConnection.ConnectionError',message => <<"connection not available and request was dropped from queue after 2703ms. This means requests are coming in and your connection pool cannot serve them fast enough. You can address this by:\n\n  1. By tracking down slow queries and making sure they are running fast enough\n  2. Increasing the pool_size (albeit it increases resource consumption)\n  3. Allow requests to wait longer by increasing :queue_...">>,...},...},...} in 'Elixir.Plug.Cowboy.Handler':exit_on_error/4 line 68 in 'Elixir.Plug.Cowboy.Handler':exit_on_error/4 line 68
2020-05-26 15:18:14.958 [error] <0.662.0> Cowboy stream 1 with ranch listener 'Elixir.User.Plug.Router.HTTP' and connection process <0.661.0> had its request process exit with reason: {{#{'__exception__' => true,'__struct__' => 'Elixir.DBConnection.ConnectionError',message => <<"connection not available and request was dropped from queue after 2703ms. This means requests are coming in and your connection pool cannot serve them fast enough. You can address this by:\n\n  1. By tracking down slow queries and making sure they are running fast enough\n  2. Increasing the pool_size (albeit it increases resource consumption)\n  3. Allow requests to wait longer by increasing :queue_...">>,...},...},...} in 'Elixir.Plug.Cowboy.Handler':exit_on_error/4 line 68
2020-05-26 15:18:41.711 [error] <0.663.0> CRASH REPORT Process <0.663.0> with 0 neighbours exited with reason: {{#{'__exception__' => true,'__struct__' => 'Elixir.DBConnection.ConnectionError',message => <<"connection not available and request was dropped from queue after 2016ms. This means requests are coming in and your connection pool cannot serve them fast enough. You can address this by:\n\n  1. By tracking down slow queries and making sure they are running fast enough\n  2. Increasing the pool_size (albeit it increases resource consumption)\n  3. Allow requests to wait longer by increasing :queue_...">>,...},...},...} in 'Elixir.Plug.Cowboy.Handler':exit_on_error/4 line 68 in 'Elixir.Plug.Cowboy.Handler':exit_on_error/4 line 68
2020-05-26 15:18:41.720 [error] <0.663.0> Cowboy stream 1 with ranch listener 'Elixir.User.Plug.Router.HTTP' and connection process <0.662.0> had its request process exit with reason: {{#{'__exception__' => true,'__struct__' => 'Elixir.DBConnection.ConnectionError',message => <<"connection not available and request was dropped from queue after 2016ms. This means requests are coming in and your connection pool cannot serve them fast enough. You can address this by:\n\n  1. By tracking down slow queries and making sure they are running fast enough\n  2. Increasing the pool_size (albeit it increases resource consumption)\n  3. Allow requests to wait longer by increasing :queue_...">>,...},...},...} in 'Elixir.Plug.Cowboy.Handler':exit_on_error/4 line 68
2020-05-26 19:07:12.829 [error] <0.665.0> CRASH REPORT Process <0.665.0> with 0 neighbours exited with reason: {{#{'__exception__' => true,'__struct__' => 'Elixir.MatchError',term => {error,{auth_failure,"ACCESS_REFUSED - Login was refused using authentication mechanism PLAIN. For details see the broker logfile."}}},[{'Elixir.User.Plug.RabbitmqProducer',send_message,1,[{file,"lib/user/plug/rabbitmq_producer.ex"},{line,9}]},{'Elixir.User.Plug.AuthController','-do_match/4-fun-1-',2,[{file,"lib/user/plug/auth_controller.ex"},{line,17}]},{'Elixir.User.Plug.AuthController',dispatch,2,[{file,"lib/plug/ro..."},...]},...]},...} in 'Elixir.Plug.Cowboy.Handler':exit_on_error/4 line 68 in 'Elixir.Plug.Cowboy.Handler':exit_on_error/4 line 68
2020-05-26 19:07:12.857 [error] <0.665.0> Cowboy stream 1 with ranch listener 'Elixir.User.Plug.Router.HTTP' and connection process <0.664.0> had its request process exit with reason: {{#{'__exception__' => true,'__struct__' => 'Elixir.MatchError',term => {error,{auth_failure,"ACCESS_REFUSED - Login was refused using authentication mechanism PLAIN. For details see the broker logfile."}}},[{'Elixir.User.Plug.RabbitmqProducer',send_message,1,[{file,"lib/user/plug/rabbitmq_producer.ex"},{line,9}]},{'Elixir.User.Plug.AuthController','-do_match/4-fun-1-',2,[{file,"lib/user/plug/auth_controller.ex"},{line,17}]},{'Elixir.User.Plug.AuthController',dispatch,2,[{file,"lib/plug/ro..."},...]},...]},...} in 'Elixir.Plug.Cowboy.Handler':exit_on_error/4 line 68
2020-05-26 19:07:58.160 [error] <0.676.0> CRASH REPORT Process <0.676.0> with 0 neighbours exited with reason: {{#{'__exception__' => true,'__struct__' => 'Elixir.MatchError',term => {error,{auth_failure,"ACCESS_REFUSED - Login was refused using authentication mechanism PLAIN. For details see the broker logfile."}}},[{'Elixir.User.Plug.RabbitmqProducer',send_message,1,[{file,"lib/user/plug/rabbitmq_producer.ex"},{line,9}]},{'Elixir.User.Plug.AuthController','-do_match/4-fun-1-',2,[{file,"lib/user/plug/auth_controller.ex"},{line,17}]},{'Elixir.User.Plug.AuthController',dispatch,2,[{file,"lib/plug/ro..."},...]},...]},...} in 'Elixir.Plug.Cowboy.Handler':exit_on_error/4 line 68 in 'Elixir.Plug.Cowboy.Handler':exit_on_error/4 line 68
2020-05-26 19:07:58.161 [error] <0.676.0> Cowboy stream 1 with ranch listener 'Elixir.User.Plug.Router.HTTP' and connection process <0.675.0> had its request process exit with reason: {{#{'__exception__' => true,'__struct__' => 'Elixir.MatchError',term => {error,{auth_failure,"ACCESS_REFUSED - Login was refused using authentication mechanism PLAIN. For details see the broker logfile."}}},[{'Elixir.User.Plug.RabbitmqProducer',send_message,1,[{file,"lib/user/plug/rabbitmq_producer.ex"},{line,9}]},{'Elixir.User.Plug.AuthController','-do_match/4-fun-1-',2,[{file,"lib/user/plug/auth_controller.ex"},{line,17}]},{'Elixir.User.Plug.AuthController',dispatch,2,[{file,"lib/plug/ro..."},...]},...]},...} in 'Elixir.Plug.Cowboy.Handler':exit_on_error/4 line 68
2020-06-02 21:51:55.666 [error] <0.664.0> CRASH REPORT Process <0.664.0> with 0 neighbours exited with reason: {{#{'__exception__' => true,'__struct__' => 'Elixir.ArgumentError',message => <<"unknown field `:password_hash` given to cast. Either the field does not exist or it is a :through association (which are read-only). The known fields are: :affiliation, :email, :first_name, :id, :last_name, :password">>},[{'Elixir.Ecto.Changeset','type!',2,[{file,"lib/ecto/changeset.ex"},{line,550}]},{'Elixir.Ecto.Changeset',process_param,7,[{file,"lib/ecto/changeset.ex"},{line,519}]},{'Elixir.Enum','-reduce/3-lists^foldl/2-0-',...},...]},...} in 'Elixir.Plug.Cowboy.Handler':exit_on_error/4 line 68 in 'Elixir.Plug.Cowboy.Handler':exit_on_error/4 line 68
2020-06-02 21:51:55.719 [error] <0.664.0> Cowboy stream 1 with ranch listener 'Elixir.User.Plug.Router.HTTP' and connection process <0.663.0> had its request process exit with reason: {{#{'__exception__' => true,'__struct__' => 'Elixir.ArgumentError',message => <<"unknown field `:password_hash` given to cast. Either the field does not exist or it is a :through association (which are read-only). The known fields are: :affiliation, :email, :first_name, :id, :last_name, :password">>},[{'Elixir.Ecto.Changeset','type!',2,[{file,"lib/ecto/changeset.ex"},{line,550}]},{'Elixir.Ecto.Changeset',process_param,7,[{file,"lib/ecto/changeset.ex"},{line,519}]},{'Elixir.Enum','-reduce/3-lists^foldl/2-0-',...},...]},...} in 'Elixir.Plug.Cowboy.Handler':exit_on_error/4 line 68
2020-06-02 21:53:35.002 [error] <0.589.0> CRASH REPORT Process <0.589.0> with 0 neighbours exited with reason: {{#{'__exception__' => true,'__struct__' => 'Elixir.ArgumentError',message => <<"argument error">>},[{erlang,byte_size,[nil],[]},{credentials_obfuscation_pbe,pad,2,[{file,"e:/mesteri/sem II/sisteme scalabile/microservices/Microservices_Elixir/deps/credentials_obfuscation/src/credentials_obfuscation_pbe.erl"},{line,137}]},{credentials_obfuscation_pbe,encrypt,5,[{file,"e:/mesteri/sem II/sisteme scalabile/microservices/Microservices_Elixir/deps/credentials_obfuscation/src/credentials_obfuscat..."},...]},...]},...} in 'Elixir.Plug.Cowboy.Handler':exit_on_error/4 line 68 in 'Elixir.Plug.Cowboy.Handler':exit_on_error/4 line 68
2020-06-02 21:53:35.012 [error] <0.589.0> Cowboy stream 1 with ranch listener 'Elixir.User.Plug.Router.HTTP' and connection process <0.588.0> had its request process exit with reason: {{#{'__exception__' => true,'__struct__' => 'Elixir.ArgumentError',message => <<"argument error">>},[{erlang,byte_size,[nil],[]},{credentials_obfuscation_pbe,pad,2,[{file,"e:/mesteri/sem II/sisteme scalabile/microservices/Microservices_Elixir/deps/credentials_obfuscation/src/credentials_obfuscation_pbe.erl"},{line,137}]},{credentials_obfuscation_pbe,encrypt,5,[{file,"e:/mesteri/sem II/sisteme scalabile/microservices/Microservices_Elixir/deps/credentials_obfuscation/src/credentials_obfuscat..."},...]},...]},...} in 'Elixir.Plug.Cowboy.Handler':exit_on_error/4 line 68
2020-06-02 22:03:17.066 [error] <0.589.0> CRASH REPORT Process <0.589.0> with 0 neighbours exited with reason: {{#{'__exception__' => true,'__struct__' => 'Elixir.ArgumentError',message => <<"argument error">>},[{erlang,byte_size,[nil],[]},{credentials_obfuscation_pbe,pad,2,[{file,"e:/mesteri/sem II/sisteme scalabile/microservices/Microservices_Elixir/deps/credentials_obfuscation/src/credentials_obfuscation_pbe.erl"},{line,137}]},{credentials_obfuscation_pbe,encrypt,5,[{file,"e:/mesteri/sem II/sisteme scalabile/microservices/Microservices_Elixir/deps/credentials_obfuscation/src/credentials_obfuscat..."},...]},...]},...} in 'Elixir.Plug.Cowboy.Handler':exit_on_error/4 line 68 in 'Elixir.Plug.Cowboy.Handler':exit_on_error/4 line 68
2020-06-02 22:03:17.148 [error] <0.589.0> Cowboy stream 1 with ranch listener 'Elixir.User.Plug.Router.HTTP' and connection process <0.588.0> had its request process exit with reason: {{#{'__exception__' => true,'__struct__' => 'Elixir.ArgumentError',message => <<"argument error">>},[{erlang,byte_size,[nil],[]},{credentials_obfuscation_pbe,pad,2,[{file,"e:/mesteri/sem II/sisteme scalabile/microservices/Microservices_Elixir/deps/credentials_obfuscation/src/credentials_obfuscation_pbe.erl"},{line,137}]},{credentials_obfuscation_pbe,encrypt,5,[{file,"e:/mesteri/sem II/sisteme scalabile/microservices/Microservices_Elixir/deps/credentials_obfuscation/src/credentials_obfuscat..."},...]},...]},...} in 'Elixir.Plug.Cowboy.Handler':exit_on_error/4 line 68
